Workbook
Name UPDATE: 'Data Sheet'!$E$1

Sheet Profit & Loss
A1: ='Data Sheet'!B1 -> ADANI ENTERPRISES LTD | H1: =UPDATE | M1: SCREENER.IN
A3: Narration | B3: ='Data Sheet'!B16 -> 42825 | C3: ='Data Sheet'!C16 -> 43190 | D3: ='Data Sheet'!D16 -> 43555 | E3: ='Data Sheet'!E16 -> 43921 | F3: ='Data Sheet'!F16 -> 44286 | G3: ='Data Sheet'!G16 -> 44651 | H3: ='Data Sheet'!H16 -> 45016 | I3: ='Data Sheet'!I16 -> 45382 | ... K3: ='Data Sheet'!K16 -> 46112 | L3: Trailing | M3: Best Case | N3: Worst Case
A4: Sales | B4: ='Data Sheet'!B17 -> 7733.37 | C4: ='Data Sheet'!C17 -> 9512.41 | D4: ='Data Sheet'!D17 -> 15461.9 | E4: ='Data Sheet'!E17 -> 16101.4 | F4: ='Data Sheet'!F17 -> 13267.59 | G4: ='Data Sheet'!G17 -> 26806.12 | H4: ='Data Sheet'!H17 -> 57843.77 | I4: ='Data Sheet'!I17 -> 31918.26 | ... K4: ='Data Sheet'!K17 -> 22916.71 | L4: =SUM(Quarters!H4:K4) -> 23056.18 | M4: =$K4+M23*K4 -> 23056.18 | N4: =$K4+N23*L4 -> 16794.258
A5: Expenses | B5: =SUM('Data Sheet'!B18,'Data Sheet'!B20:B24, -1*'Data Sheet'!B19) -> 7164.06 | C5: =SUM('Data Sheet'!C18,'Data Sheet'!C20:C24, -1*'Data Sheet'!C19) -> 8900.32 | D5: =SUM('Data Sheet'!D18,'Data Sheet'!D20:D24, -1*'Data Sheet'!D19) -> 14513.63 | E5: =SUM('Data Sheet'!E18,'Data Sheet'!E20:E24, -1*'Data Sheet'!E19) -> 15355.46 | F5: =SUM('Data Sheet'!F18,'Data Sheet'!F20:F24, -1*'Data Sheet'!F19) -> 12263.95 | G5: =SUM('Data Sheet'!G18,'Data Sheet'!G20:G24, -1*'Data Sheet'!G19) -> 25500.04 | H5: =SUM('Data Sheet'!H18,'Data Sheet'!H20:H24, -1*'Data Sheet'!H19) -> 56039.91 | I5: =SUM('Data Sheet'!I18,'Data Sheet'!I20:I24, -1*'Data Sheet'!I19) -> 28979.66 | ... K5: =SUM('Data Sheet'!K18,'Data Sheet'!K20:K24, -1*'Data Sheet'!K19) -> 21022.32 | L5: =SUM(Quarters!H5:K5) -> 21161.8 | M5: =M4-M6 -> 20953.585 | N5: =N4-N6 -> 15738.597
A6: Operating Profit | B6: =B4-B5 -> 569.31 | C6: =C4-C5 -> 612.09 | D6: =D4-D5 -> 948.27 | E6: =E4-E5 -> 745.94 | F6: =F4-F5 -> 1003.64 | G6: =G4-G5 -> 1306.08 | H6: =H4-H5 -> 1803.86 | I6: =I4-I5 -> 2938.6 | ... K6: =K4-K5 -> 1894.39 | L6: =SUM(Quarters!H6:K6) -> 1894.38 | M6: =M4*M24 -> 2102.5946 | N6: =N4*N24 -> 1055.6608
A7: Other Income | B7: ='Data Sheet'!B25 -> 679.87 | C7: ='Data Sheet'!C25 -> 435.15 | D7: ='Data Sheet'!D25 -> 363.52 | E7: ='Data Sheet'!E25 -> 725.59 | F7: ='Data Sheet'!F25 -> 179.06 | G7: ='Data Sheet'!G25 -> 503.23 | H7: ='Data Sheet'!H25 -> 1202.03 | I7: ='Data Sheet'!I25 -> 1638.8 | ... K7: ='Data Sheet'!K25 -> 12200.9 | L7: =SUM(Quarters!H7:K7) -> 12200.9 | M7: 0 | N7: 0
A8: Depreciation | B8: ='Data Sheet'!B26 -> 78.86 | C8: ='Data Sheet'!C26 -> 87.41 | D8: ='Data Sheet'!D26 -> 101.19 | E8: ='Data Sheet'!E26 -> 120.97 | F8: ='Data Sheet'!F26 -> 121.51 | G8: ='Data Sheet'!G26 -> 124.73 | H8: ='Data Sheet'!H26 -> 131.04 | I8: ='Data Sheet'!I26 -> 142.59 | ... K8: ='Data Sheet'!K26 -> 188.3 | L8: =SUM(Quarters!H8:K8) -> 188.31 | M8: =+$L8 -> 188.31 | N8: =+$L8 -> 188.31
A9: Interest | B9: ='Data Sheet'!B27 -> 781.8 | C9: ='Data Sheet'!C27 -> 666.35 | D9: ='Data Sheet'!D27 -> 581.07 | E9: ='Data Sheet'!E27 -> 381.01 | F9: ='Data Sheet'!F27 -> 505.93 | G9: ='Data Sheet'!G27 -> 571.33 | H9: ='Data Sheet'!H27 -> 664.13 | I9: ='Data Sheet'!I27 -> 638.19 | ... K9: ='Data Sheet'!K27 -> 1747.51 | L9: =SUM(Quarters!H9:K9) -> 1747.5 | M9: =+$L9 -> 1747.5 | N9: =+$L9 -> 1747.5
A10: Profit before tax | B10: ='Data Sheet'!B28 -> 388.52 | C10: ='Data Sheet'!C28 -> 293.48 | D10: ='Data Sheet'!D28 -> 629.53 | E10: ='Data Sheet'!E28 -> 969.55 | F10: ='Data Sheet'!F28 -> 555.26 | G10: ='Data Sheet'!G28 -> 1113.25 | H10: ='Data Sheet'!H28 -> 2210.72 | I10: ='Data Sheet'!I28 -> 3796.62 | ... K10: ='Data Sheet'!K28 -> 12159.48 | L10: =SUM(Quarters!H10:K10) -> 12159.47 | M10: =M6+M7-SUM(M8:M9) -> 166.78465 | N10: =N6+N7-SUM(N8:N9) -> -880.14921
A11: Tax | B11: ='Data Sheet'!B29 -> 166.88 | C11: ='Data Sheet'!C29 -> 96.45 | D11: ='Data Sheet'!D29 -> 142.29 | E11: ='Data Sheet'!E29 -> 270.66 | F11: ='Data Sheet'!F29 -> 186.45 | G11: ='Data Sheet'!G29 -> 392.55 | H11: ='Data Sheet'!H29 -> 587.99 | I11: ='Data Sheet'!I29 -> 952.36 | ... K11: ='Data Sheet'!K29 -> 781.42 | L11: =SUM(Quarters!H11:K11) -> 781.42 | M11: =IF($L10>0,$L11/$L10,0) -> 0.064264314 | N11: =IF($L10>0,$L11/$L10,0) -> 0.064264314
A12: Net profit | B12: ='Data Sheet'!B30 -> 221.64 | C12: ='Data Sheet'!C30 -> 197.03 | D12: ='Data Sheet'!D30 -> 487.24 | E12: ='Data Sheet'!E30 -> 698.89 | F12: ='Data Sheet'!F30 -> 368.81 | G12: ='Data Sheet'!G30 -> 720.7 | H12: ='Data Sheet'!H30 -> 1622.73 | I12: ='Data Sheet'!I30 -> 2844.26 | ... K12: ='Data Sheet'!K30 -> 11378.06 | L12: =SUM(Quarters!H12:K12) -> 11378.05 | M12: =M10-M11*M10 -> 156.06635 | N12: =N10-N11*N10 -> -823.58703
A13: EPS | B13: =IF('Data Sheet'!B93>0,B12/'Data Sheet'!B93,0) -> 1.7993181 | C13: =IF('Data Sheet'!C93>0,C12/'Data Sheet'!C93,0) -> 1.5995291 | D13: =IF('Data Sheet'!D93>0,D12/'Data Sheet'!D93,0) -> 3.9555123 | E13: =IF('Data Sheet'!E93>0,E12/'Data Sheet'!E93,0) -> 5.6737295 | F13: =IF('Data Sheet'!F93>0,F12/'Data Sheet'!F93,0) -> 2.9940737 | G13: =IF('Data Sheet'!G93>0,G12/'Data Sheet'!G93,0) -> 5.8507875 | H13: =IF('Data Sheet'!H93>0,H12/'Data Sheet'!H93,0) -> 12.709352 | I13: =IF('Data Sheet'!I93>0,I12/'Data Sheet'!I93,0) -> 22.276472 | ... K13: =IF('Data Sheet'!K93>0,K12/'Data Sheet'!K93,0) -> 88.092753 | L13: =IF('Data Sheet'!$B6>0,'Profit & Loss'!L12/'Data Sheet'!$B6,0) -> 87.472976 | M13: =IF('Data Sheet'!$B6>0,'Profit & Loss'!M12/'Data Sheet'!$B6,0) -> 1.1998179 | N13: =IF('Data Sheet'!$B6>0,'Profit & Loss'!N12/'Data Sheet'!$B6,0) -> -6.3316305
A14: Price to earning | B14: =IF(B15>0,B15/B13,"") -> 39.081473 | C14: =IF(C15>0,C15/C13,"") -> 63.337389 | D14: =IF(D15>0,D15/D13,"") -> 35.967529 | E14: =IF(E15>0,E15/E13,"") -> 23.511872 | F14: =IF(F15>0,F15/F13,"") -> 333.88624 | G14: =IF(G15>0,G15/G13,"") -> 333.84737 | H14: =IF(H15>0,H15/H13,"") -> 133.52688 | I14: =IF(I15>0,I15/I13,"") -> 139.13962 | ... K14: =IF(K15>0,K15/K13,"") -> 19.96532 | L14: =IF(L13>0,L15/L13,0) -> 33.651536 | M14: =M25 -> 60.201409 | N14: =N25 -> 33.651536
A15: Price | B15: ='Data Sheet'!B90 -> 70.32 | C15: ='Data Sheet'!C90 -> 101.31 | D15: ='Data Sheet'!D90 -> 142.27 | E15: ='Data Sheet'!E90 -> 133.4 | F15: ='Data Sheet'!F90 -> 999.68 | G15: ='Data Sheet'!G90 -> 1953.27 | H15: ='Data Sheet'!H90 -> 1697.04 | I15: ='Data Sheet'!I90 -> 3099.54 | ... K15: ='Data Sheet'!K90 -> 1758.8 | L15: ='Data Sheet'!B8 -> 2943.6 | M15: =M13*M14 -> 72.230726 | N15: =N13*N14 -> -213.06909
A17: RATIOS:
A18: Dividend Payout | B18: =IF('Data Sheet'!B30>0, 'Data Sheet'!B31/'Data Sheet'!B30, 0) -> 0.198475 | C18: =IF('Data Sheet'!C30>0, 'Data Sheet'!C31/'Data Sheet'!C30, 0) -> 0.22326549 | D18: =IF('Data Sheet'!D30>0, 'Data Sheet'!D31/'Data Sheet'!D30, 0) -> 0.090284049 | E18: =IF('Data Sheet'!E30>0, 'Data Sheet'!E31/'Data Sheet'!E30, 0) -> 0.15736382 | F18: =IF('Data Sheet'!F30>0, 'Data Sheet'!F31/'Data Sheet'!F30, 0) -> 0.29820233 | G18: =IF('Data Sheet'!G30>0, 'Data Sheet'!G31/'Data Sheet'!G30, 0) -> 0.15260164 | H18: =IF('Data Sheet'!H30>0, 'Data Sheet'!H31/'Data Sheet'!H30, 0) -> 0.084302379 | I18: =IF('Data Sheet'!I30>0, 'Data Sheet'!I31/'Data Sheet'!I30, 0) -> 0.052104941 | ... K18: =IF('Data Sheet'!K30>0, 'Data Sheet'!K31/'Data Sheet'!K30, 0) -> 0.014766138
A19: OPM | B19: =IF(B6>0,B6/B4,0) -> 0.073617323 | C19: =IF(C6>0,C6/C4,0) -> 0.06434647 | D19: =IF(D6>0,D6/D4,0) -> 0.061329461 | E19: =IF(E6>0,E6/E4,0) -> 0.046327649 | F19: =IF(F6>0,F6/F4,0) -> 0.075645991 | G19: =IF(G6>0,G6/G4,0) -> 0.048723202 | H19: =IF(H6>0,H6/H4,0) -> 0.031185035 | I19: =IF(I6>0,I6/I4,0) -> 0.092066422 | ... L19: =IF(L6>0,L6/L4,0) -> 0.082163654
G22: TRENDS: | H22: 10 YEARS | I22: 7 YEARS | J22: 5 YEARS | K22: 3 YEARS | L22: RECENT | M22: BEST | N22: WORST
G23: Sales Growth | H23: =IF(B4=0,"",POWER($K4/B4,1/9)-1) -> 0.12828908 | I23: =IF(D4=0,"",POWER($K4/D4,1/7)-1) -> 0.057822433 | J23: =IF(F4=0,"",POWER($K4/F4,1/5)-1) -> 0.11550635 | K23: =IF(H4=0,"",POWER($K4/H4, 1/3)-1) -> -0.26554494 | L23: =IF(ISERROR(MAX(IF(J4=0,"",(K4-J4)/J4),IF(K4=0,"",(L4-K4)/K4))),"",MAX(IF(J4=0,"",(K4-J4)/J4),IF(K4=0,"",(L4-K4)/K4))) -> 0.0060859521 | M23: =MAX(K23:L23) -> 0.0060859521 | N23: =MIN(H23:L23) -> -0.26554494
G24: OPM | H24: =IF(SUM(B4:$K$4)=0,"",SUMPRODUCT(B19:$K$19,B4:$K$4)/SUM(B4:$K$4)) -> 0.063181525 | I24: =IF(SUM(E4:$K$4)=0,"",SUMPRODUCT(E19:$K$19,E4:$K$4)/SUM(E4:$K$4)) -> 0.062858436 | J24: =IF(SUM(G4:$K$4)=0,"",SUMPRODUCT(G19:$K$19,G4:$K$4)/SUM(G4:$K$4)) -> 0.063439518 | K24: =IF(SUM(I4:$K$4)=0, "", SUMPRODUCT(I19:$K$19,I4:$K$4)/SUM(I4:$K$4)) -> 0.091194406 | L24: =L19 -> 0.082163654 | M24: =MAX(K24:L24) -> 0.091194406 | N24: =MIN(H24:L24) -> 0.062858436
G25: Price to Earning | H25: =IF(ISERROR(AVERAGEIF(B14:$L14,">0")),"",AVERAGEIF(B14:$L14,">0")) -> 109.45131 | I25: =IF(ISERROR(AVERAGEIF(E14:$L14,">0")),"",AVERAGEIF(E14:$L14,">0")) -> 133.19725 | J25: =IF(ISERROR(AVERAGEIF(G14:$L14,">0")),"",AVERAGEIF(G14:$L14,">0")) -> 118.02998 | K25: =IF(ISERROR(AVERAGEIF(I14:$L14,">0")),"",AVERAGEIF(I14:$L14,">0")) -> 60.201409 | L25: =L14 -> 33.651536 | M25: =MAX(K25:L25) -> 60.201409 | N25: =MIN(H25:L25) -> 33.651536

Sheet Quarters
A1: ='Profit & Loss'!A1 -> ADANI ENTERPRISES LTD | E1: =UPDATE | J1: SCREENER.IN
A3: Narration | B3: ='Data Sheet'!B41 -> 45291 | C3: ='Data Sheet'!C41 -> 45382 | D3: ='Data Sheet'!D41 -> 45473 | E3: ='Data Sheet'!E41 -> 45565 | F3: ='Data Sheet'!F41 -> 45657 | G3: ='Data Sheet'!G41 -> 45747 | H3: ='Data Sheet'!H41 -> 45838 | I3: ='Data Sheet'!I41 -> 45930 | ... K3: ='Data Sheet'!K41 -> 46112
A4: Sales | B4: ='Data Sheet'!B42 -> 7960.79 | C4: ='Data Sheet'!C42 -> 9210.18 | D4: ='Data Sheet'!D42 -> 7800.75 | E4: ='Data Sheet'!E42 -> 6586.92 | F4: ='Data Sheet'!F42 -> 6156.76 | G4: ='Data Sheet'!G42 -> 6164.55 | H4: ='Data Sheet'!H42 -> 5875.6 | I4: ='Data Sheet'!I42 -> 5066.43 | ... K4: ='Data Sheet'!K42 -> 6810.08
A5: Expenses | B5: ='Data Sheet'!B43 -> 7171.4 | C5: ='Data Sheet'!C43 -> 8274.97 | D5: ='Data Sheet'!D43 -> 7090.24 | E5: ='Data Sheet'!E43 -> 5848.4 | F5: ='Data Sheet'!F43 -> 5531.64 | G5: ='Data Sheet'!G43 -> 5645.31 | H5: ='Data Sheet'!H43 -> 5296.25 | I5: ='Data Sheet'!I43 -> 4400.35 | ... K5: ='Data Sheet'!K43 -> 6635.11
A6: Operating Profit | B6: ='Data Sheet'!B50 -> 789.39 | C6: ='Data Sheet'!C50 -> 935.21 | D6: ='Data Sheet'!D50 -> 710.51 | E6: ='Data Sheet'!E50 -> 738.52 | F6: ='Data Sheet'!F50 -> 625.12 | G6: ='Data Sheet'!G50 -> 519.24 | H6: ='Data Sheet'!H50 -> 579.35 | I6: ='Data Sheet'!I50 -> 666.08 | ... K6: ='Data Sheet'!K50 -> 174.97
A7: Other Income | B7: ='Data Sheet'!B44 -> 378.03 | C7: ='Data Sheet'!C44 -> 347.93 | D7: ='Data Sheet'!D44 -> 317.37 | E7: ='Data Sheet'!E44 -> 353.27 | F7: ='Data Sheet'!F44 -> 426.26 | G7: ='Data Sheet'!G44 -> 4364.25 | H7: ='Data Sheet'!H44 -> 492.38 | I7: ='Data Sheet'!I44 -> 4271.65 | ... K7: ='Data Sheet'!K44 -> 919.02
A8: Depreciation | B8: ='Data Sheet'!B45 -> 35.51 | C8: ='Data Sheet'!C45 -> 37.41 | D8: ='Data Sheet'!D45 -> 37.57 | E8: ='Data Sheet'!E45 -> 38.73 | F8: ='Data Sheet'!F45 -> 37.56 | G8: ='Data Sheet'!G45 -> 40.98 | H8: ='Data Sheet'!H45 -> 41.75 | I8: ='Data Sheet'!I45 -> 42.71 | ... K8: ='Data Sheet'!K45 -> 57.44
A9: Interest | B9: ='Data Sheet'!B46 -> 167.68 | C9: ='Data Sheet'!C46 -> 207.82 | D9: ='Data Sheet'!D46 -> 172.72 | E9: ='Data Sheet'!E46 -> 206.44 | F9: ='Data Sheet'!F46 -> 289.84 | G9: ='Data Sheet'!G46 -> 339.58 | H9: ='Data Sheet'!H46 -> 349.63 | I9: ='Data Sheet'!I46 -> 469.8 | ... K9: ='Data Sheet'!K46 -> 408.55
A10: Profit before tax | B10: ='Data Sheet'!B47 -> 964.23 | C10: ='Data Sheet'!C47 -> 1037.91 | D10: ='Data Sheet'!D47 -> 817.59 | E10: ='Data Sheet'!E47 -> 846.62 | F10: ='Data Sheet'!F47 -> 723.98 | G10: ='Data Sheet'!G47 -> 4502.93 | H10: ='Data Sheet'!H47 -> 680.35 | I10: ='Data Sheet'!I47 -> 4425.22 | ... K10: ='Data Sheet'!K47 -> 628
A11: Tax | B11: ='Data Sheet'!B48 -> 245.77 | C11: ='Data Sheet'!C48 -> 261.2 | D11: ='Data Sheet'!D48 -> 215.33 | E11: ='Data Sheet'!E48 -> 218.63 | F11: ='Data Sheet'!F48 -> 189.39 | G11: ='Data Sheet'!G48 -> 227.54 | H11: ='Data Sheet'!H48 -> 176.31 | I11: ='Data Sheet'!I48 -> 190.76 | ... K11: ='Data Sheet'!K48 -> 284.44
A12: Net profit | B12: ='Data Sheet'!B49 -> 718.46 | C12: ='Data Sheet'!C49 -> 776.71 | D12: ='Data Sheet'!D49 -> 602.26 | E12: ='Data Sheet'!E49 -> 627.99 | F12: ='Data Sheet'!F49 -> 534.59 | G12: ='Data Sheet'!G49 -> 4275.39 | H12: ='Data Sheet'!H49 -> 504.04 | I12: ='Data Sheet'!I49 -> 4234.46 | ... K12: ='Data Sheet'!K49 -> 343.56
A14: OPM | B14: =IF(B4>0,B6/B4,"") -> 0.099159757 | C14: =IF(C4>0,C6/C4,"") -> 0.1015409 | D14: =IF(D4>0,D6/D4,"") -> 0.091082268 | E14: =IF(E4>0,E6/E4,"") -> 0.11211917 | F14: =IF(F4>0,F6/F4,"") -> 0.10153392 | G14: =IF(G4>0,G6/G4,"") -> 0.084229992 | H14: =IF(H4>0,H6/H4,"") -> 0.098602696 | I14: =IF(I4>0,I6/I4,"") -> 0.1314693 | ... K14: =IF(K4>0,K6/K4,"") -> 0.025692797

Sheet Balance Sheet
A1: ='Profit & Loss'!A1 -> ADANI ENTERPRISES LTD | E1: =UPDATE | J1: SCREENER.IN
A3: Narration | B3: ='Data Sheet'!B56 -> 42825 | C3: ='Data Sheet'!C56 -> 43190 | D3: ='Data Sheet'!D56 -> 43555 | E3: ='Data Sheet'!E56 -> 43921 | F3: ='Data Sheet'!F56 -> 44286 | G3: ='Data Sheet'!G56 -> 44651 | H3: ='Data Sheet'!H56 -> 45016 | I3: ='Data Sheet'!I56 -> 45382 | ... K3: ='Data Sheet'!K56 -> 46112
A4: Equity Share Capital | B4: ='Data Sheet'!B57 -> 109.98 | C4: ='Data Sheet'!C57 -> 109.98 | D4: ='Data Sheet'!D57 -> 109.98 | E4: ='Data Sheet'!E57 -> 109.98 | F4: ='Data Sheet'!F57 -> 109.98 | G4: ='Data Sheet'!G57 -> 109.98 | H4: ='Data Sheet'!H57 -> 114 | I4: ='Data Sheet'!I57 -> 114 | ... K4: ='Data Sheet'!K57 -> 129.24
A5: Reserves | B5: ='Data Sheet'!B58 -> 3657.2 | C5: ='Data Sheet'!C58 -> 3798.42 | D5: ='Data Sheet'!D58 -> 3138.84 | E5: ='Data Sheet'!E58 -> 3651.02 | F5: ='Data Sheet'!F58 -> 4018.01 | G5: ='Data Sheet'!G58 -> 5130.68 | H5: ='Data Sheet'!H58 -> 13819.78 | I5: ='Data Sheet'!I58 -> 16525.54 | ... K5: ='Data Sheet'!K58 -> 62649.75
A6: Borrowings | B6: ='Data Sheet'!B59 -> 7212.83 | C6: ='Data Sheet'!C59 -> 6682.71 | D6: ='Data Sheet'!D59 -> 2865.37 | E6: ='Data Sheet'!E59 -> 3011.63 | F6: ='Data Sheet'!F59 -> 2918.87 | G6: ='Data Sheet'!G59 -> 4410.57 | H6: ='Data Sheet'!H59 -> 3106.05 | I6: ='Data Sheet'!I59 -> 5893.24 | ... K6: ='Data Sheet'!K59 -> 11008.1
A7: Other Liabilities | B7: ='Data Sheet'!B60 -> 3678.27 | C7: ='Data Sheet'!C60 -> 4819.55 | D7: ='Data Sheet'!D60 -> 8559.3 | E7: ='Data Sheet'!E60 -> 7112.94 | F7: ='Data Sheet'!F60 -> 5945.4 | G7: ='Data Sheet'!G60 -> 12000.65 | H7: ='Data Sheet'!H60 -> 23097.44 | I7: ='Data Sheet'!I60 -> 19647.59 | ... K7: ='Data Sheet'!K60 -> 8437.95
A8: Total | B8: ='Data Sheet'!B61 -> 14658.28 | C8: ='Data Sheet'!C61 -> 15410.66 | D8: ='Data Sheet'!D61 -> 14673.49 | E8: ='Data Sheet'!E61 -> 13885.57 | F8: ='Data Sheet'!F61 -> 12992.26 | G8: ='Data Sheet'!G61 -> 21651.88 | H8: ='Data Sheet'!H61 -> 40137.27 | I8: ='Data Sheet'!I61 -> 42180.37 | ... K8: ='Data Sheet'!K61 -> 82225.04
A10: Net Block | B10: ='Data Sheet'!B62 -> 1171.38 | C10: ='Data Sheet'!C62 -> 1262.77 | D10: ='Data Sheet'!D62 -> 1557.67 | E10: ='Data Sheet'!E62 -> 1528.14 | F10: ='Data Sheet'!F62 -> 1427.79 | G10: ='Data Sheet'!G62 -> 1683.41 | H10: ='Data Sheet'!H62 -> 1667.72 | I10: ='Data Sheet'!I62 -> 1540.17 | ... K10: ='Data Sheet'!K62 -> 2452.66
A11: Capital Work in Progress | B11: ='Data Sheet'!B63 -> 621.6 | C11: ='Data Sheet'!C63 -> 413.9 | D11: ='Data Sheet'!D63 -> 211.39 | E11: ='Data Sheet'!E63 -> 219.61 | F11: ='Data Sheet'!F63 -> 453.12 | G11: ='Data Sheet'!G63 -> 511.44 | H11: ='Data Sheet'!H63 -> 649.28 | I11: ='Data Sheet'!I63 -> 752.34 | ... K11: ='Data Sheet'!K63 -> 1082.76
A12: Investments | B12: ='Data Sheet'!B64 -> 3091.2 | C12: ='Data Sheet'!C64 -> 3008.97 | D12: ='Data Sheet'!D64 -> 1944.24 | E12: ='Data Sheet'!E64 -> 2274.91 | F12: ='Data Sheet'!F64 -> 2465.31 | G12: ='Data Sheet'!G64 -> 3437.35 | H12: ='Data Sheet'!H64 -> 9947.99 | I12: ='Data Sheet'!I64 -> 14070.99 | ... K12: ='Data Sheet'!K64 -> 28275.19
A13: Other Assets | B13: ='Data Sheet'!B65 -> 9774.1 | C13: ='Data Sheet'!C65 -> 10725.02 | D13: ='Data Sheet'!D65 -> 10960.19 | E13: ='Data Sheet'!E65 -> 9862.91 | F13: ='Data Sheet'!F65 -> 8646.04 | G13: ='Data Sheet'!G65 -> 16019.68 | H13: ='Data Sheet'!H65 -> 27872.28 | I13: ='Data Sheet'!I65 -> 25816.87 | ... K13: ='Data Sheet'!K65 -> 50414.43
A14: Total | B14: ='Data Sheet'!B66 -> 14658.28 | C14: ='Data Sheet'!C66 -> 15410.66 | D14: ='Data Sheet'!D66 -> 14673.49 | E14: ='Data Sheet'!E66 -> 13885.57 | F14: ='Data Sheet'!F66 -> 12992.26 | G14: ='Data Sheet'!G66 -> 21651.88 | H14: ='Data Sheet'!H66 -> 40137.27 | I14: ='Data Sheet'!I66 -> 42180.37 | ... K14: ='Data Sheet'!K66 -> 82225.04
A16: Working Capital | B16: =B13-B7 -> 6095.83 | C16: =C13-C7 -> 5905.47 | D16: =D13-D7 -> 2400.89 | E16: =E13-E7 -> 2749.97 | F16: =F13-F7 -> 2700.64 | G16: =G13-G7 -> 4019.03 | H16: =H13-H7 -> 4774.84 | I16: =I13-I7 -> 6169.28 | ... K16: =K13-K7 -> 41976.48
A17: Debtors | B17: ='Data Sheet'!B67 -> 2923.44 | C17: ='Data Sheet'!C67 -> 2635.37 | D17: ='Data Sheet'!D67 -> 5182.05 | E17: ='Data Sheet'!E67 -> 3846.48 | F17: ='Data Sheet'!F67 -> 2661.31 | G17: ='Data Sheet'!G67 -> 3516.19 | H17: ='Data Sheet'!H67 -> 4688.27 | I17: ='Data Sheet'!I67 -> 4220.82 | ... K17: ='Data Sheet'!K67 -> 4107.52
A18: Inventory | B18: ='Data Sheet'!B68 -> 594.56 | C18: ='Data Sheet'!C68 -> 1294.42 | D18: ='Data Sheet'!D68 -> 1901.88 | E18: ='Data Sheet'!E68 -> 1527.47 | F18: ='Data Sheet'!F68 -> 1099.19 | G18: ='Data Sheet'!G68 -> 4843.83 | H18: ='Data Sheet'!H68 -> 4085.46 | I18: ='Data Sheet'!I68 -> 3006.61 | ... K18: ='Data Sheet'!K68 -> 2065.93
A20: Debtor Days | B20: =IF('Profit & Loss'!B4>0,'Balance Sheet'!B17/('Profit & Loss'!B4/365),0) -> 137.98067 | C20: =IF('Profit & Loss'!C4>0,'Balance Sheet'!C17/('Profit & Loss'!C4/365),0) -> 101.12159 | D20: =IF('Profit & Loss'!D4>0,'Balance Sheet'!D17/('Profit & Loss'!D4/365),0) -> 122.32961 | E20: =IF('Profit & Loss'!E4>0,'Balance Sheet'!E17/('Profit & Loss'!E4/365),0) -> 87.195225 | F20: =IF('Profit & Loss'!F4>0,'Balance Sheet'!F17/('Profit & Loss'!F4/365),0) -> 73.214363 | G20: =IF('Profit & Loss'!G4>0,'Balance Sheet'!G17/('Profit & Loss'!G4/365),0) -> 47.877475 | H20: =IF('Profit & Loss'!H4>0,'Balance Sheet'!H17/('Profit & Loss'!H4/365),0) -> 29.583455 | I20: =IF('Profit & Loss'!I4>0,'Balance Sheet'!I17/('Profit & Loss'!I4/365),0) -> 48.26702 | ... K20: =IF('Profit & Loss'!K4>0,'Balance Sheet'!K17/('Profit & Loss'!K4/365),0) -> 65.421468
A21: Inventory Turnover | B21: =IF('Balance Sheet'!B18>0,'Profit & Loss'!B4/'Balance Sheet'!B18,0) -> 13.006879 | C21: =IF('Balance Sheet'!C18>0,'Profit & Loss'!C4/'Balance Sheet'!C18,0) -> 7.3487817 | D21: =IF('Balance Sheet'!D18>0,'Profit & Loss'!D4/'Balance Sheet'!D18,0) -> 8.1297979 | E21: =IF('Balance Sheet'!E18>0,'Profit & Loss'!E4/'Balance Sheet'!E18,0) -> 10.541222 | F21: =IF('Balance Sheet'!F18>0,'Profit & Loss'!F4/'Balance Sheet'!F18,0) -> 12.070334 | G21: =IF('Balance Sheet'!G18>0,'Profit & Loss'!G4/'Balance Sheet'!G18,0) -> 5.5340753 | H21: =IF('Balance Sheet'!H18>0,'Profit & Loss'!H4/'Balance Sheet'!H18,0) -> 14.158447 | I21: =IF('Balance Sheet'!I18>0,'Profit & Loss'!I4/'Balance Sheet'!I18,0) -> 10.616029 | ... K21: =IF('Balance Sheet'!K18>0,'Profit & Loss'!K4/'Balance Sheet'!K18,0) -> 11.092685
A23: Return on Equity | B23: =IF(SUM('Balance Sheet'!B4:B5)>0,'Profit & Loss'!B12/SUM('Balance Sheet'!B4:B5),"") -> 0.05883446 | C23: =IF(SUM('Balance Sheet'!C4:C5)>0,'Profit & Loss'!C12/SUM('Balance Sheet'!C4:C5),"") -> 0.050411933 | D23: =IF(SUM('Balance Sheet'!D4:D5)>0,'Profit & Loss'!D12/SUM('Balance Sheet'!D4:D5),"") -> 0.14997445 | E23: =IF(SUM('Balance Sheet'!E4:E5)>0,'Profit & Loss'!E12/SUM('Balance Sheet'!E4:E5),"") -> 0.18582558 | F23: =IF(SUM('Balance Sheet'!F4:F5)>0,'Profit & Loss'!F12/SUM('Balance Sheet'!F4:F5),"") -> 0.089343724 | G23: =IF(SUM('Balance Sheet'!G4:G5)>0,'Profit & Loss'!G12/SUM('Balance Sheet'!G4:G5),"") -> 0.13752085 | H23: =IF(SUM('Balance Sheet'!H4:H5)>0,'Profit & Loss'!H12/SUM('Balance Sheet'!H4:H5),"") -> 0.11646014 | I23: =IF(SUM('Balance Sheet'!I4:I5)>0,'Profit & Loss'!I12/SUM('Balance Sheet'!I4:I5),"") -> 0.17093381 | ... K23: =IF(SUM('Balance Sheet'!K4:K5)>0,'Profit & Loss'!K12/SUM('Balance Sheet'!K4:K5),"") -> 0.18123993
A24: Return on Capital Emp | C24: =IF((B4+B5+B6+C4+C5+C6)>0,('Profit & Loss'!C10+'Profit & Loss'!C9)*2/(B4+B5+B6+C4+C5+C6),"") -> 0.088992134 | D24: =IF((C4+C5+C6+D4+D5+D6)>0,('Profit & Loss'!D10+'Profit & Loss'!D9)*2/(C4+C5+C6+D4+D5+D6),"") -> 0.14493604 | E24: =IF((D4+D5+D6+E4+E5+E6)>0,('Profit & Loss'!E10+'Profit & Loss'!E9)*2/(D4+D5+D6+E4+E5+E6),"") -> 0.2096033 | F24: =IF((E4+E5+E6+F4+F5+F6)>0,('Profit & Loss'!F10+'Profit & Loss'!F9)*2/(E4+E5+E6+F4+F5+F6),"") -> 0.15357875 | G24: =IF((F4+F5+F6+G4+G5+G6)>0,('Profit & Loss'!G10+'Profit & Loss'!G9)*2/(F4+F5+F6+G4+G5+G6),"") -> 0.20176918 | H24: =IF((G4+G5+G6+H4+H5+H6)>0,('Profit & Loss'!H10+'Profit & Loss'!H9)*2/(G4+G5+G6+H4+H5+H6),"") -> 0.2154167 | I24: =IF((H4+H5+H6+I4+I5+I6)>0,('Profit & Loss'!I10+'Profit & Loss'!I9)*2/(H4+H5+H6+I4+I5+I6),"") -> 0.22413533 | J24: =IF((I4+I5+I6+J4+J5+J6)>0,('Profit & Loss'!J10+'Profit & Loss'!J9)*2/(I4+I5+I6+J4+J5+J6),"") -> 0.25457906 | K24: =IF((J4+J5+J6+K4+K5+K6)>0,('Profit & Loss'!K10+'Profit & Loss'!K9)*2/(J4+J5+J6+K4+K5+K6),"") -> 0.24545694

Sheet Cash Flow
A1: ='Balance Sheet'!A1 -> ADANI ENTERPRISES LTD | E1: =UPDATE | J1: SCREENER.IN
A3: Narration | B3: ='Data Sheet'!B81 -> 42825 | C3: ='Data Sheet'!C81 -> 43190 | D3: ='Data Sheet'!D81 -> 43555 | E3: ='Data Sheet'!E81 -> 43921 | F3: ='Data Sheet'!F81 -> 44286 | G3: ='Data Sheet'!G81 -> 44651 | H3: ='Data Sheet'!H81 -> 45016 | I3: ='Data Sheet'!I81 -> 45382 | ... K3: ='Data Sheet'!K81 -> 46112
A4: Cash from Operating Activity | B4: ='Data Sheet'!B82 -> -156.13 | C4: ='Data Sheet'!C82 -> 986.12 | D4: ='Data Sheet'!D82 -> 1907.96 | E4: ='Data Sheet'!E82 -> 601.38 | F4: ='Data Sheet'!F82 -> 1557.26 | G4: ='Data Sheet'!G82 -> 2105.01 | H4: ='Data Sheet'!H82 -> 11187.32 | I4: ='Data Sheet'!I82 -> 507.88 | ... K4: ='Data Sheet'!K82 -> -3240.15
A5: Cash from Investing Activity | B5: ='Data Sheet'!B83 -> 645.69 | C5: ='Data Sheet'!C83 -> 171.64 | D5: ='Data Sheet'!D83 -> 2396.77 | E5: ='Data Sheet'!E83 -> 91.27 | F5: ='Data Sheet'!F83 -> -1317.55 | G5: ='Data Sheet'!G83 -> -3125.86 | H5: ='Data Sheet'!H83 -> -16008.75 | I5: ='Data Sheet'!I83 -> -2465.88 | ... K5: ='Data Sheet'!K83 -> -15490.93
A6: Cash from Financing Activity | B6: ='Data Sheet'!B84 -> -308.26 | C6: ='Data Sheet'!C84 -> -1144.74 | D6: ='Data Sheet'!D84 -> -4436.85 | E6: ='Data Sheet'!E84 -> -422.4 | F6: ='Data Sheet'!F84 -> -632.09 | G6: ='Data Sheet'!G84 -> 1065.74 | H6: ='Data Sheet'!H84 -> 5110.32 | I6: ='Data Sheet'!I84 -> 2099.57 | ... K6: ='Data Sheet'!K84 -> 21005.78
A7: Net Cash Flow | B7: ='Data Sheet'!B85 -> 181.3 | C7: ='Data Sheet'!C85 -> 13.02 | D7: ='Data Sheet'!D85 -> -132.12 | E7: ='Data Sheet'!E85 -> 270.25 | F7: ='Data Sheet'!F85 -> -392.38 | G7: ='Data Sheet'!G85 -> 44.89 | H7: ='Data Sheet'!H85 -> 288.89 | I7: ='Data Sheet'!I85 -> 141.57 | ... K7: ='Data Sheet'!K85 -> 2274.7

Sheet Customization
A1: How to use it?
A3: You can customize this workbook as you want.
B4: You can add custom formating, add conditional formating, add your own formulas… do ANYTHING.
B5: Please don't edit the "Data Sheet" only.
A7: After customization, you can upload this back on Screener.
B8: Upload on: | C8: https://www.screener.in/excel/
A10: Download your customized workbooks now onwards.
B11: Now whenever you will "Export to excel" from Screener, it will export your customized file.
A14: TESTING:
B15: This is a testing feature currently.
B16: You can report any formula errors on the worksheet at: support@screener.in

Sheet Data Sheet
A1: COMPANY NAME | B1: ADANI ENTERPRISES LTD | E1: =IF(B2<>B3, "A NEW VERSION OF THE WORKSHEET IS AVAILABLE", "")
A2: LATEST VERSION | B2: 2.1 | E2: PLEASE DO NOT MAKE ANY CHANGES TO THIS SHEET
A3: CURRENT VERSION | B3: 2.1
A5: META
A6: Number of shares | B6: =IF(B9>0, B9/B8, 0) -> 130.07503
A7: Face Value | B7: 1
A8: Current Price | B8: 2943.6
A9: Market Capitalization | B9: 382888.86
A15: PROFIT & LOSS
A16: Report Date | B16: 42825 | C16: 43190 | D16: 43555 | E16: 43921 | F16: 44286 | G16: 44651 | H16: 45016 | I16: 45382 | J16: 45747 | K16: 46112
A17: Sales | B17: 7733.37 | C17: 9512.41 | D17: 15461.9 | E17: 16101.4 | F17: 13267.59 | G17: 26806.12 | H17: 57843.77 | I17: 31918.26 | J17: 26599.63 | K17: 22916.71
A18: Raw Material Cost | B18: 5962.23 | C18: 8494.22 | D18: 13230.36 | E18: 12303.72 | F18: 10125.04 | G18: 26608.32 | H18: 47796.59 | I18: 21982.11 | J18: 17361.55 | K18: 15030.35
A19: Change in Inventory | B19: 30.34 | C19: 730.06 | D19: 605.27 | E19: -376.27 | F19: -434.03 | G19: 3743.31 | H19: -757.94 | I19: -1087.59 | J19: -1105.36 | K19: 168.75
A20: Power and Fuel | B20: 22.04 | C20: 19.89 | D20: 30.37 | E20: 44.19 | F20: 34.4 | G20: 38.47 | H20: 43.38 | I20: 48.32 | J20: 50.9 | K20: 40.93
A21: Other Mfr. Exp | B21: 735.94 | C21: 697.9 | D21: 1046.12 | E21: 1823.98 | F21: 1081.39 | G21: 1710.32 | H21: 5380.52 | I21: 4225.26 | J21: 3704.29 | K21: 3658.52
A22: Employee Cost | B22: 247.07 | C22: 234.72 | D22: 239.36 | E22: 275.87 | F22: 312.36 | G22: 382.06 | H22: 652.29 | I22: 702.46 | J22: 839.67 | K22: 1010.37
A23: Selling and admin | B23: 162.89 | C23: 102.76 | D23: 201.74 | E23: 246.98 | F23: 261.59 | G23: 239.55 | H23: 427.36 | I23: 554.61 | J23: 592.78 | K23: 738.09
A24: Other Expenses | B24: 64.23 | C24: 80.89 | D24: 370.95 | E24: 284.45 | F24: 15.14 | G24: 264.63 | H24: 981.83 | I24: 379.31 | J24: 351.69 | K24: 712.81
A25: Other Income | B25: 679.87 | C25: 435.15 | D25: 363.52 | E25: 725.59 | F25: 179.06 | G25: 503.23 | H25: 1202.03 | I25: 1638.8 | J25: 5461.15 | K25: 12200.9
A26: Depreciation | B26: 78.86 | C26: 87.41 | D26: 101.19 | E26: 120.97 | F26: 121.51 | G26: 124.73 | H26: 131.04 | I26: 142.59 | J26: 154.85 | K26: 188.3
A27: Interest | B27: 781.8 | C27: 666.35 | D27: 581.07 | E27: 381.01 | F27: 505.93 | G27: 571.33 | H27: 664.13 | I27: 638.19 | J27: 1008.57 | K27: 1747.51
... A31: Dividend Amount | B31: 43.99 | C31: 43.99 | D31: 43.99 | E31: 109.98 | F31: 109.98 | G31: 109.98 | H31: 136.8 | I31: 148.2 | J31: 150.05 | K31: 168.01
A40: Quarters
A41: Report Date | B41: 45291 | C41: 45382 | D41: 45473 | E41: 45565 | F41: 45657 | G41: 45747 | H41: 45838 | I41: 45930 | J41: 46022 | K41: 46112
A42: Sales | B42: 7960.79 | C42: 9210.18 | D42: 7800.75 | E42: 6586.92 | F42: 6156.76 | G42: 6164.55 | H42: 5875.6 | I42: 5066.43 | J42: 5304.07 | K42: 6810.08
A43: Expenses | B43: 7171.4 | C43: 8274.97 | D43: 7090.24 | E43: 5848.4 | F43: 5531.64 | G43: 5645.31 | H43: 5296.25 | I43: 4400.35 | J43: 4830.09 | K43: 6635.11
A44: Other Income | B44: 378.03 | C44: 347.93 | D44: 317.37 | E44: 353.27 | F44: 426.26 | G44: 4364.25 | H44: 492.38 | I44: 4271.65 | J44: 6517.85 | K44: 919.02
A45: Depreciation | B45: 35.51 | C45: 37.41 | D45: 37.57 | E45: 38.73 | F45: 37.56 | G45: 40.98 | H45: 41.75 | I45: 42.71 | J45: 46.41 | K45: 57.44
A46: Interest | B46: 167.68 | C46: 207.82 | D46: 172.72 | E46: 206.44 | F46: 289.84 | G46: 339.58 | H46: 349.63 | I46: 469.8 | J46: 519.52 | K46: 408.55
A47: Profit before tax | B47: 964.23 | C47: 1037.91 | D47: 817.59 | E47: 846.62 | F47: 723.98 | G47: 4502.93 | H47: 680.35 | I47: 4425.22 | J47: 6425.9 | K47: 628
A48: Tax | B48: 245.77 | C48: 261.2 | D48: 215.33 | E48: 218.63 | F48: 189.39 | G48: 227.54 | H48: 176.31 | I48: 190.76 | J48: 129.91 | K48: 284.44
A49: Net profit | B49: 718.46 | C49: 776.71 | D49: 602.26 | E49: 627.99 | F49: 534.59 | G49: 4275.39 | H49: 504.04 | I49: 4234.46 | J49: 6295.99 | K49: 343.56
A50: Operating Profit | B50: 789.39 | C50: 935.21 | D50: 710.51 | E50: 738.52 | F50: 625.12 | G50: 519.24 | H50: 579.35 | I50: 666.08 | J50: 473.98 | K50: 174.97
A55: BALANCE SHEET
A56: Report Date | B56: 42825 | C56: 43190 | D56: 43555 | E56: 43921 | F56: 44286 | G56: 44651 | H56: 45016 | I56: 45382 | J56: 45747 | K56: 46112
A57: Equity Share Capital | B57: 109.98 | C57: 109.98 | D57: 109.98 | E57: 109.98 | F57: 109.98 | G57: 109.98 | H57: 114 | I57: 114 | J57: 115.42 | K57: 129.24
A58: Reserves | B58: 3657.2 | C58: 3798.42 | D58: 3138.84 | E58: 3651.02 | F58: 4018.01 | G58: 5130.68 | H58: 13819.78 | I58: 16525.54 | J58: 26583.47 | K58: 62649.75
A59: Borrowings | B59: 7212.83 | C59: 6682.71 | D59: 2865.37 | E59: 3011.63 | F59: 2918.87 | G59: 4410.57 | H59: 3106.05 | I59: 5893.24 | J59: 12829.13 | K59: 11008.1
A60: Other Liabilities | B60: 3678.27 | C60: 4819.55 | D60: 8559.3 | E60: 7112.94 | F60: 5945.4 | G60: 12000.65 | H60: 23097.44 | I60: 19647.59 | J60: 10810.11 | K60: 8437.95
A61: Total | B61: 14658.28 | C61: 15410.66 | D61: 14673.49 | E61: 13885.57 | F61: 12992.26 | G61: 21651.88 | H61: 40137.27 | I61: 42180.37 | J61: 50338.13 | K61: 82225.04
...

Sheet Shareholding Pattern
A1: Category | B1: 45078 | C1: 45170 | D1: 45261 | E1: 45352 | F1: 45444 | G1: 45536 | H1: 45627 | I1: 45717 | J1: 45809 | K1: 45901 | L1: 45992 | M1: 46082
A2: Promoters | B2: 0.6765 | C2: 0.7261 | D2: 72.61% | E2: 0.7261 | F2: 0.7472 | G2: 0.7489 | H2: 0.7397 | I2: 0.7397 | J2: 0.7397 | K2: 0.7397 | L2: 0.7397 | M2: 0.7467
A3: FIIs | B3: 0.1934 | C3: 0.1452 | D3: 0.1465 | E3: 0.1441 | F3: 0.1173 | G3: 0.1131 | H3: 0.1172 | I3: 0.1171 | J3: 0.1155 | K3: 0.1172 | L3: 0.1164 | M3: 0.108
A4: DIIs | B4: 0.0546 | C4: 0.0565 | D4: 0.0544 | E4: 0.0577 | F4: 0.0602 | G4: 0.0646 | H4: 0.0661 | I4: 0.0686 | J4: 0.0704 | K4: 0.0684 | L4: 0.0671 | M4: 0.067
A5: Public | B5: 0.0754 | C5: 0.0723 | D5: 0.073 | E5: 0.0722 | F5: 0.0753 | G5: 0.0736 | H5: 0.0768 | I5: 0.0745 | J5: 0.0744 | K5: 0.0747 | L5: 0.0766 | M5: 0.0784
A6: No. of Shareholders | B6: 661255 | C6: 566232 | D6: 561309 | E6: 537342 | F6: 643975 | G6: 584928 | H6: 667210 | I6: 655946 | J6: 621739 | K6: 618413 | L6: 642614 | M6: 664882

Sheet Peer comparison
A1: S.No. | B1: Name | C1: CMP Rs. | D1: P/E | E1: Mar Cap Rs.Cr. | F1: Div Yld % | G1: Qtr Profit Var % | H1: Sales Qtr Rs.Cr. | I1: Qtr Sales Var % | J1: ROCE %
A2: 1 | B2: Adani Enterp. | C2: 2942.5 | D2: 332.65 | E2: 382968.26 | F2: 0.04 | G2: -42.83 | H2: 6810.08 | I2: 10.47 | J2: 7.59
A3: 2 | B3: Starlineps Enter | C3: 10.84 | D3: 66.16 | E3: 393.63 | F3: 0 | G3: 465.91 | H3: 27.82 | I3: 100.14 | J3: 7.05
A4: 3 | B4: Rajdarshan Inds | C4: 37.5 | E4: 12.73 | F4: 0 | G4: -51.72 | H4: 0.11 | I4: 57.14 | J4: 0.19
